<?xml version="1.0"?>
<robot name="purebot" xmlns:xacro="http://ros.org/wiki/xacro">

    <xacro:property name="PI" value="3.1415926535897931" />

    <xacro:property name="wheel_radius" value="0.050" />
    <xacro:property name="wheel_width" value="0.0505" />

    <link name="base_footprint"></link>  

    <joint name="base_link_joint" type="fixed">
        <origin xyz="0 0 0.05" rpy="0 0 0" />
        <parent link="base_footprint"/>
        <child link="base_link" />
        <dynamics damping="300"/>
    </joint>

    <link name="base_link">
        <visual>
            <origin xyz="0 0 0" rpy="0 0 0" />
            <geometry>
                <mesh filename="package://purebot/meshes/nexus_base_link.STL" scale="0.001 0.001 0.001"/>
            </geometry>
        </visual>
        <collision>
        <origin xyz="0 0 0"/>
            <geometry>
                <mesh filename="package://purebot/meshes/nexus_base_link_collision.STL" scale="0.001 0.001 0.001"/>
            </geometry>
        </collision>
        <inertial>
            <origin xyz="-0.01103 0 0.002" rpy="0 0 0"/>
            <mass value="4.844"/>
            <inertia
              ixx="0.18819942" ixy="0" ixz="0"
              iyy="0.57333716" iyz="0"
              izz="0.74201740"/>
        </inertial>
    </link>

    <joint name='base_pole_joint' type='fixed'>
        <parent link="base_link"/>
        <child link="pole_link"/>
        <origin xyz="0 0 0.5" rpy=" 0 0 0"/>
        <dynamics damping="300"/>
    </joint>

    <link name='pole_link'>
        <inertial>
            <mass value="2.674875"/>
            <inertia
              ixx="0.2297" ixy="0" ixz="0"
              iyy="0.022968" iyz="0"
              izz="0.126"/>
            <origin xyz="0 0 0" rpy="0 0 0"/>
        </inertial>
        <visual name='visual'>
            <origin xyz="0 0 0" rpy="0 0 0"/>
            <geometry>
                <box size="0.052 0.052 1"/>
            </geometry>
        </visual>
        <collision name='collision'>
            <origin xyz="0 0 0" rpy="0 0 0"/>
            <geometry>
                <box size="0.052 0.052 1"/>
            </geometry>
        </collision>
    </link>
    
    <joint name='pole_arms_joint' type='prismatic'>
        <parent link="pole_link"/>
        <child link="arms_link"/>
        <origin xyz="0 0 0" rpy=" 0 0 0"/>
        <limit lower="-0.2" upper="0.5" effort="1" velocity="0.5"/>
        <axis xyz="0 0 1"/>
        <dynamics damping="1.2" friction="3"/>
    </joint>
    
    <link name='arms_link'>
        <inertial>
            <mass value="1.078612"/>
            <inertia
              ixx="0.490204" ixy="0" ixz="0"
              iyy="0.0490204" iyz="0"
              izz="0.797687"/>
            <origin xyz="0 0 0" rpy="0 0 0"/>
        </inertial>
        <visual name='visual'>
            <origin xyz="0 0 0" rpy="0 0 0"/>
            <geometry>
                <box size="0.05 0.504 0.05"/>
            </geometry>
        </visual>
        <collision name='collision'>
            <origin xyz="0 0 0" rpy="0 0 0"/>
            <geometry>
                <box size="0.05 0.304 0.05"/>
            </geometry>
        </collision>
    </link>

    <joint name="upper_left_wheel_shaft_joint" type="fixed">
        <origin xyz="0.150 0.108 0.0" rpy="0 0 0" />
        <parent link="base_link"/>
        <child link="upper_left_wheel_shaft" />
        <dynamics damping="300" />
    </joint>

    <link name="upper_left_wheel_shaft">
        <visual>
            <origin xyz="0 0 0" rpy="0 0 0" />
            <geometry>
                <mesh filename="package://purebot/meshes/wheel_shaft.STL" scale="0.001 0.001 0.001"/>
            </geometry>
        </visual>
        <collision>
            <origin xyz="0 0 0"/>
            <geometry>
                <mesh filename="package://purebot/meshes/wheel_shaft.STL" scale="0.001 0.001 0.001"/>
            </geometry>
        </collision>
        <inertial>
            <origin xyz="0 0 0" rpy="0 0 0"/>
            <mass value="1.355"/>
            <inertia
              ixx="0.21370" ixy="0" ixz="0"
              iyy="0.09966" iyz="0"
              izz="0.21370"/>
        </inertial>
    </link>

    <joint name="lower_left_wheel_shaft_joint" type="fixed">
        <origin xyz="-0.150 0.108 0.0" rpy="0 0 0" />
        <parent link="base_link"/>
        <child link="lower_left_wheel_shaft" />
        <dynamics damping="1.5" />
    </joint>

    <link name="lower_left_wheel_shaft">
        <visual>
            <origin xyz="0 0 0" rpy="0 0 0" />
            <geometry>
                <mesh filename="package://purebot/meshes/wheel_shaft.STL" scale="0.001 0.001 0.001"/>
            </geometry>
        </visual>
        <collision>
            <origin xyz="0 0 0"/>
            <geometry>
                <mesh filename="package://purebot/meshes/wheel_shaft.STL" scale="0.001 0.001 0.001"/>
            </geometry>
        </collision>
        <inertial>
            <origin xyz="0 0 0" rpy="0 0 0"/>
            <mass value="1.355"/>
            <inertia
              ixx="0.21370" ixy="0" ixz="0"
              iyy="0.09966" iyz="0"
              izz="0.21370"/>
        </inertial>
    </link>

    <joint name="upper_right_wheel_shaft_joint" type="fixed">
        <origin xyz="0.150 -0.108 0.0" rpy="${PI} 0 0" />
        <parent link="base_link"/>
        <child link="upper_right_wheel_shaft" />
        <dynamics damping="300" />
    </joint>

    <link name="upper_right_wheel_shaft">
        <visual>
            <origin xyz="0 0 0" rpy="0 0 0" />
            <geometry>
                <mesh filename="package://purebot/meshes/wheel_shaft.STL" scale="0.001 0.001 0.001"/>
            </geometry>
        </visual>
        <collision>
            <origin xyz="0 0 0"/>
            <geometry>
                <mesh filename="package://purebot/meshes/wheel_shaft.STL" scale="0.001 0.001 0.001"/>
            </geometry>
        </collision>
        <inertial>
            <origin xyz="0 0 0" rpy="0 0 0"/>
            <mass value="1.355"/>
            <inertia
              ixx="0.21370" ixy="0" ixz="0"
              iyy="0.09966" iyz="0"
              izz="0.21370"/>
        </inertial>
    </link>

    <joint name="lower_right_wheel_shaft_joint" type="fixed">
        <origin xyz="-0.150 -0.108 0.0" rpy="${PI} 0 0" />
        <parent link="base_link"/>
        <child link="lower_right_wheel_shaft" />
        <dynamics damping="300" />
    </joint>

    <link name="lower_right_wheel_shaft">
        <visual>
            <origin xyz="0 0 0" rpy="0 0 0" />
            <geometry>
                <mesh filename="package://purebot/meshes/wheel_shaft.STL" scale="0.001 0.001 0.001"/>
            </geometry>
        </visual>
        <collision>
            <origin xyz="0 0 0"/>
            <geometry>
                <mesh filename="package://purebot/meshes/wheel_shaft.STL" scale="0.001 0.001 0.001"/>
            </geometry>
        </collision>
        <inertial>
            <origin xyz="0 0 0" rpy="0 0 0"/>
            <mass value="1.355"/>
            <inertia
              ixx="0.21370" ixy="0" ixz="0"
              iyy="0.09966" iyz="0"
              izz="0.21370"/>
        </inertial>
    </link>

    <joint name="upper_left_wheel_joint" type="continuous">
        <origin xyz="0 0.042 0" rpy="0 0 0" />
        <parent link="upper_left_wheel_shaft"/>
        <child link="upper_left_wheel" />
        <axis xyz="0 1 0"/>
    </joint>
  
    <link name="upper_left_wheel">
        <visual>
            <origin xyz="0 0 0" rpy="0 0 0" />
            <geometry>
                <mesh filename="package://purebot/meshes/mecanum_wheel_left.STL" scale="0.001 0.001 0.001"/>
            </geometry>
        </visual>
        <collision>
            <origin xyz="0 0 0" rpy="${PI/2} 0 0"/>
            <geometry>
                <cylinder radius="${wheel_radius}" length="${wheel_width}"/>
            </geometry>
        </collision>
        <inertial>
            <origin xyz="0 0 0" rpy="0 0 0"/>
            <mass value="2.0844"/>
            <inertia
              ixx="0.324824" ixy="0" ixz="0"
              iyy="0.0480000" iyz="0"
              izz="0.324824"/>
        </inertial>
    </link>

    <joint name="lower_left_wheel_joint" type="continuous">
        <origin xyz="0 0.042 0" rpy="0 0 0" />
        <parent link="lower_left_wheel_shaft"/>
        <child link="lower_left_wheel" />
        <axis xyz="0 1 0"/>
    </joint>

    <link name="lower_left_wheel">
        <visual>
            <origin xyz="0 0 0" rpy="0 0 0" />
            <geometry>
                <mesh filename="package://purebot/meshes/mecanum_wheel_right.STL" scale="0.001 0.001 0.001"/>
            </geometry>
        </visual>
        <collision>
            <origin xyz="0 0 0" rpy="${PI/2} 0 0"/>
            <geometry>
                <cylinder radius="${wheel_radius}" length="${wheel_width}"/>
            </geometry>
        </collision>
        <inertial>
            <origin xyz="0 0 0" rpy="0 0 0"/>
            <mass value="2.0844"/>
            <inertia
              ixx="0.324824" ixy="0" ixz="0"
              iyy="0.0480000" iyz="0"
              izz="0.324824"/>
        </inertial>
    </link>

    <joint name="upper_right_wheel_joint" type="continuous">
        <origin xyz="0 0.042 0" rpy="0 0 0" />
        <parent link="upper_right_wheel_shaft"/>
        <child link="upper_right_wheel" />
        <axis xyz="0 1 0"/>
    </joint>

    <link name="upper_right_wheel">
        <visual>
            <origin xyz="0 0 0" rpy="0 0 0" />
            <geometry>
                <mesh filename="package://purebot/meshes/mecanum_wheel_right.STL" scale="0.001 0.001 0.001"/>
            </geometry>
        </visual>
        <collision>
            <origin xyz="0 0 0" rpy="${PI/2} 0 0"/>
            <geometry>
                <cylinder radius="${wheel_radius}" length="${wheel_width}"/>
            </geometry>
        </collision>
        <inertial>
            <origin xyz="0.0 0.0 0.0" rpy="0 0 0"/>
            <mass value="2.0844"/>
            <inertia
              ixx="0.324824" ixy="0" ixz="0"
              iyy="0.0480000" iyz="0"
              izz="0.324824"/>
        </inertial>
    </link>
  
    <joint name="lower_right_wheel_joint" type="continuous">
        <origin xyz="0 0.042 0" rpy="0 0 0" />
        <parent link="lower_right_wheel_shaft"/>
        <child link="lower_right_wheel" />
        <axis xyz="0 1 0"/>
        <joint_properties damping="1.1" friction="1.0" />
    </joint>

    <link name="lower_right_wheel">
        <visual>
            <origin xyz="0 0 0" rpy="0 0 0" />
            <geometry>
                <mesh filename="package://purebot/meshes/mecanum_wheel_left.STL" scale="0.001 0.001 0.001"/>
            </geometry>
        </visual>
        <collision>
            <origin xyz="0 0 0" rpy="${PI/2} 0 0"/>
            <geometry>
                <cylinder radius="${wheel_radius}" length="${wheel_width}"/>
            </geometry>
        </collision>
        <inertial>
            <origin xyz="0 0 0" rpy="0 0 0"/>
            <mass value="2.0844"/>
            <inertia
              ixx="0.324824" ixy="0" ixz="0"
              iyy="0.0480000" iyz="0"
              izz="0.324824"/>
        </inertial>
    </link>



    <!-- Include Gazebo File -->
    <xacro:include filename="$(find purebot)/urdf/purebot.gazebo.xacro" />

    <!-- D435i Camera-->
    <xacro:include filename="$(find realsense2_description)/urdf/_d435i.urdf.xacro"/>
    <xacro:sensor_d435i parent="base_link" name="D435i_camera" use_nominal_extrinsics="True">
        <origin xyz="0.15 0.0 0.37" rpy="0.0 0.0 0.0"/>
    </xacro:sensor_d435i> -->

</robot>

